Workbook

Sheet Portada
A1: PAQUETE DE CIERRE MENSUAL — EJEMPLO DIDÁCTICO
A3: Fecha | B3: =TODAY()
A4: Elaboró | B4: Alondra Abril Alarcon Alvarez
A6: Contenido:
A7: Tarifa + Cotizador · Cédula de Reservas · Resumen ejecutivo · Control

Sheet Tarifa
A1: TARIFA — factores y cotizador
A2: Prima base | B2: 226.09
A4: FACTOR: Cobertura | B4: Factor | D4: COTIZADOR | E4: Selección | F4: Factor
A5: Amplia | B5: 1 | D5: Cobertura | E5: Amplia | F5: =VLOOKUP(E5,$A$5:$B$7,2, FALSE)
A6: Limitada | B6: 0.66564934 | D6: Sexo | E6: Hombre | F6: =VLOOKUP(E6,$A$10:$B$11,2, FALSE)
A7: RC | B7: 0.89667897 | D7: Combustible | E7: Diesel | F7: =VLOOKUP(E7,$A$14:$B$16,2, FALSE)
D8: Edad (banda) | E8: (17, 30] | F8: =VLOOKUP(E8,$A$19:$B$25,2, FALSE)
A9: FACTOR: Sexo | B9: Factor | D9: Potencia (banda) | E9: (40, 50] | F9: =VLOOKUP(E9,$A$28:$B$32,2, FALSE)
A10: Hombre | B10: 1 | D10: Bonus (banda) | E10: (-1, 0] | F10: =VLOOKUP(E10,$A$35:$B$40,2, FALSE)
A11: Mujer | B11: 0.96996124
D12: PRIMA PURA | E12: =B2*PRODUCT(F5:F10)
A13: FACTOR: Combustible | B13: Factor
A14: Diesel | B14: 1
A15: Gasolina | B15: 0.84663791
A18: FACTOR: Edad (banda) | B18: Factor
A19: (17, 30] | B19: 1
A20: (30, 35] | B20: 0.82617719
A21: (35, 45] | B21: 0.74085947
A22: (45, 50] | B22: 0.80294934
A23: (50, 55] | B23: 0.65201533
A24: (55, 60] | B24: 0.58044444
A25: (60, 95] | B25: 0.646944
A27: FACTOR: Potencia (banda) | B27: Factor
A28: (40, 50] | B28: 1
A29: (50, 60] | B29: 0.95007831
A30: (60, 70] | B30: 1.024391
A31: (70, 250] | B31: 1.1836284
A32: (9, 40] | B32: 0.93526134
A34: FACTOR: Bonus (banda) | B34: Factor
A35: (-1, 0] | B35: 1
A36: (0, 1] | B36: 1.2316878
A37: (1, 2] | B37: 1.2721167
A38: (10, 25] | B38: 2.5312182
A39: (2, 5] | B39: 1.5210408
A40: (5, 10] | B40: 1.8654016

Sheet Reservas
A1: CÉDULA DE RESERVAS
A4: TRIÁNGULO DE SINIESTROS ACUMULADOS
A5: Año origen | B5: 12 | C5: 24 | D5: 36 | E5: 48 | F5: 60 | G5: 72 | H5: 84 | I5: 96 | J5: 108 | K5: 120
A6: 1981 | B6: 5012 | C6: 8269 | D6: 10907 | E6: 11805 | F6: 13539 | G6: 16181 | H6: 18009 | I6: 18608 | J6: 18662 | K6: 18834
A7: 1982 | B7: 106 | C7: 4285 | D7: 5396 | E7: 10666 | F7: 13782 | G7: 15599 | H7: 15496 | I7: 16169 | J7: 16704
A8: 1983 | B8: 3410 | C8: 8992 | D8: 13873 | E8: 16141 | F8: 18735 | G8: 22214 | H8: 22863 | I8: 23466
A9: 1984 | B9: 5655 | C9: 11555 | D9: 15766 | E9: 21266 | F9: 23425 | G9: 26083 | H9: 27067
A10: 1985 | B10: 1092 | C10: 9565 | D10: 15836 | E10: 22169 | F10: 25955 | G10: 26180
A11: 1986 | B11: 1513 | C11: 6445 | D11: 11702 | E11: 12935 | F11: 15852
A12: 1987 | B12: 557 | C12: 4020 | D12: 10946 | E12: 12314
A13: 1988 | B13: 1351 | C13: 6947 | D13: 13112
A14: 1989 | B14: 3133 | C14: 5395
A15: 1990 | B15: 2063
A17: FACTORES DE DESARROLLO (LDF)
A18: Periodo | B18: 12-24 | C18: 24-36 | D18: 36-48 | E18: 48-60 | F18: 60-72 | G18: 72-84 | H18: 84-96 | I18: 96-108 | J18: 108-120 | K18: Tail
A19: Factor | B19: 2.9993587 | C19: 1.6235228 | D19: 1.2708881 | E19: 1.1716746 | F19: 1.1133849 | G19: 1.0419346 | H19: 1.0332636 | I19: 1.0169365 | J19: 1.0092166 | K19: 1
A21: RESERVAS POR AÑO DE ORIGEN
A22: Año | B22: Últ. acumulado | C22: CDF | D22: Ultimate | E22: IBNR
A23: 1981 | B23: =K6 | C23: =K19 | D23: =B23*C23 | E23: =D23-B23
A24: 1982 | B24: =J7 | C24: =PRODUCT(J19:J19)*K19 | D24: =B24*C24 | E24: =D24-B24
A25: 1983 | B25: =I8 | C25: =PRODUCT(I19:J19)*K19 | D25: =B25*C25 | E25: =D25-B25
A26: 1984 | B26: =H9 | C26: =PRODUCT(H19:J19)*K19 | D26: =B26*C26 | E26: =D26-B26
A27: 1985 | B27: =G10 | C27: =PRODUCT(G19:J19)*K19 | D27: =B27*C27 | E27: =D27-B27
A28: 1986 | B28: =F11 | C28: =PRODUCT(F19:J19)*K19 | D28: =B28*C28 | E28: =D28-B28
A29: 1987 | B29: =E12 | C29: =PRODUCT(E19:J19)*K19 | D29: =B29*C29 | E29: =D29-B29
A30: 1988 | B30: =D13 | C30: =PRODUCT(D19:J19)*K19 | D30: =B30*C30 | E30: =D30-B30
A31: 1989 | B31: =C14 | C31: =PRODUCT(C19:J19)*K19 | D31: =B31*C31 | E31: =D31-B31
A32: 1990 | B32: =B15 | C32: =PRODUCT(B19:J19)*K19 | D32: =B32*C32 | E32: =D32-B32
A33: TOTAL | E33: =SUM(E23:E32)
A35: COMPARATIVO CHAIN-LADDER vs BORNHUETTER-FERGUSON
A36: Año | B36: IBNR CL | C36: IBNR BF | D36: Diferencia
A37: 1981 | B37: =E23 | C37: 0 | D37: =C37-B37
A38: 1982 | B38: =E24 | C38: 130.13699 | D38: =C38-B38
A39: 1983 | B39: =E25 | C39: 384.52108 | D39: =C39-B39
A40: 1984 | B40: =E26 | C40: 897.7846 | D40: =C40-B40
A41: 1985 | B41: =E27 | C41: 1566.7564 | D41: =C41-B41
A42: 1986 | B42: =E28 | C42: 3227.8702 | D42: =C42-B42
A43: 1987 | B43: =E29 | C43: 5512.0727 | D43: =C43-B43
A44: 1988 | B44: =E30 | C44: 8514.4353 | D44: =C44-B44
A45: 1989 | B45: =E31 | C45: 12943.278 | D45: =C45-B45
...

Sheet Resumen
A1: RESUMEN EJECUTIVO
A3: Prima base (tarifa) | B3: ='Tarifa'!B2
A4: IBNR total — Chain-Ladder | B4: ='Reservas'!E33
A5: IBNR total — Bornh.-Ferguson | B5: ='Reservas'!C47

Sheet Control
A1: CONTROL — reconciliación Python vs Excel
A3: PRICING (prima de un perfil de referencia)
A4: Prima Python | B4: 187.90812
A5: Prima Excel | B5: =226.0916042720405*VLOOKUP("RC",Tarifa!$A$5:$B$7,2,FALSE)*VLOOKUP("Mujer",Tarifa!$A$10:$B$11,2,FALSE)*VLOOKUP("Gasolina",Tarifa!$A$14:$B$16,2,FALSE)*VLOOKUP("(60, 95]",Tarifa!$A$19:$B$25,2,FALSE)*VLOOKUP("(9, 40]",Tarifa!$A$28:$B$32,2,FALSE)*VLOOKUP("(5, 10]",Tarifa!$A$35:$B$40,2,FALSE)
A6: Diferencia (≈0) | B6: =B5-B4
A9: RESERVAS (IBNR total)
A10: IBNR Python | B10: 52135.228
A11: IBNR Excel | B11: ='Reservas'!E33
A12: Diferencia (≈0) | B12: =B11-B10
